2022-04-01 16:03:42,320 INFO    MainThread:369081 [wandb_setup.py:_flush():75] Loading settings from /home/cuongnq1/.config/wandb/settings
2022-04-01 16:03:42,320 INFO    MainThread:369081 [wandb_setup.py:_flush():75] Loading settings from /home/cuongnq1/graph-neural-pde/src/wandb/settings
2022-04-01 16:03:42,320 INFO    MainThread:369081 [wandb_setup.py:_flush():75] Loading settings from environment variables: {}
2022-04-01 16:03:42,320 INFO    MainThread:369081 [wandb_setup.py:_flush():75] Inferring run settings from compute environment: {'program_relpath': 'src/run_grand_ex.py', 'program': '/home/cuongnq1/graph-neural-pde/src/run_grand_ex.py'}
2022-04-01 16:03:42,320 INFO    MainThread:369081 [wandb_init.py:_log_setup():405] Logging user logs to /home/cuongnq1/graph-neural-pde/src/wandb/run-20220401_160342-xnl2baoi/logs/debug.log
2022-04-01 16:03:42,320 INFO    MainThread:369081 [wandb_init.py:_log_setup():406] Logging internal logs to /home/cuongnq1/graph-neural-pde/src/wandb/run-20220401_160342-xnl2baoi/logs/debug-internal.log
2022-04-01 16:03:42,321 INFO    MainThread:369081 [wandb_init.py:init():439] calling init triggers
2022-04-01 16:03:42,321 INFO    MainThread:369081 [wandb_init.py:init():442] wandb.init called with sweep_config: {}
config: {}
2022-04-01 16:03:42,321 INFO    MainThread:369081 [wandb_init.py:init():492] starting backend
2022-04-01 16:03:42,321 INFO    MainThread:369081 [backend.py:_multiprocessing_setup():99] multiprocessing start_methods=fork,spawn,forkserver, using: spawn
2022-04-01 16:03:42,336 INFO    MainThread:369081 [backend.py:ensure_launched():219] starting backend process...
2022-04-01 16:03:42,345 INFO    MainThread:369081 [backend.py:ensure_launched():224] started backend process with pid: 369142
2022-04-01 16:03:42,347 INFO    MainThread:369081 [wandb_init.py:init():501] backend started and connected
2022-04-01 16:03:42,354 INFO    MainThread:369081 [wandb_init.py:init():565] updated telemetry
2022-04-01 16:03:42,375 INFO    MainThread:369081 [wandb_init.py:init():596] communicating run to backend with 30 second timeout
2022-04-01 16:04:12,377 INFO    MainThread:369081 [interface_shared.py:_communicate_run():322] couldn't get run from backend
2022-04-01 16:04:12,377 ERROR   MainThread:369081 [wandb_init.py:init():601] backend process timed out
2022-04-01 16:04:12,377 ERROR   MainThread:369081 [wandb_init.py:init():610] encountered error: Error communicating with wandb process
try: wandb.init(settings=wandb.Settings(start_method='fork'))
or:  wandb.init(settings=wandb.Settings(start_method='thread'))
For more info see: https://docs.wandb.ai/library/init#init-start-error
2022-04-01 16:04:23,222 ERROR   Thread-3  :369081 [retry.py:__call__():126] Retry attempt failed:
Traceback (most recent call last):
  File "/home/cuongnq1/anaconda3/envs/grand/lib/python3.9/site-packages/urllib3/connectionpool.py", line 449, in _make_request
    six.raise_from(e, None)
  File "<string>", line 3, in raise_from
  File "/home/cuongnq1/anaconda3/envs/grand/lib/python3.9/site-packages/urllib3/connectionpool.py", line 444, in _make_request
    httplib_response = conn.getresponse()
  File "/home/cuongnq1/anaconda3/envs/grand/lib/python3.9/http/client.py", line 1377, in getresponse
    response.begin()
  File "/home/cuongnq1/anaconda3/envs/grand/lib/python3.9/http/client.py", line 320, in begin
    version, status, reason = self._read_status()
  File "/home/cuongnq1/anaconda3/envs/grand/lib/python3.9/http/client.py", line 281, in _read_status
    line = str(self.fp.readline(_MAXLINE + 1), "iso-8859-1")
  File "/home/cuongnq1/anaconda3/envs/grand/lib/python3.9/socket.py", line 704, in readinto
    return self._sock.recv_into(b)
  File "/home/cuongnq1/anaconda3/envs/grand/lib/python3.9/ssl.py", line 1241, in recv_into
    return self.read(nbytes, buffer)
  File "/home/cuongnq1/anaconda3/envs/grand/lib/python3.9/ssl.py", line 1099, in read
    return self._sslobj.read(len, buffer)
socket.timeout: The read operation timed out

During handling of the above exception, another exception occurred:

Traceback (most recent call last):
  File "/home/cuongnq1/anaconda3/envs/grand/lib/python3.9/site-packages/requests/adapters.py", line 440, in send
    resp = conn.urlopen(
  File "/home/cuongnq1/anaconda3/envs/grand/lib/python3.9/site-packages/urllib3/connectionpool.py", line 785, in urlopen
    retries = retries.increment(
  File "/home/cuongnq1/anaconda3/envs/grand/lib/python3.9/site-packages/urllib3/util/retry.py", line 550, in increment
    raise six.reraise(type(error), error, _stacktrace)
  File "/home/cuongnq1/anaconda3/envs/grand/lib/python3.9/site-packages/urllib3/packages/six.py", line 770, in reraise
    raise value
  File "/home/cuongnq1/anaconda3/envs/grand/lib/python3.9/site-packages/urllib3/connectionpool.py", line 703, in urlopen
    httplib_response = self._make_request(
  File "/home/cuongnq1/anaconda3/envs/grand/lib/python3.9/site-packages/urllib3/connectionpool.py", line 451, in _make_request
    self._raise_timeout(err=e, url=url, timeout_value=read_timeout)
  File "/home/cuongnq1/anaconda3/envs/grand/lib/python3.9/site-packages/urllib3/connectionpool.py", line 340, in _raise_timeout
    raise ReadTimeoutError(
urllib3.exceptions.ReadTimeoutError: HTTPSConnectionPool(host='api.wandb.ai', port=443): Read timed out. (read timeout=10)

During handling of the above exception, another exception occurred:

Traceback (most recent call last):
  File "/home/cuongnq1/anaconda3/envs/grand/lib/python3.9/site-packages/wandb/sdk/lib/retry.py", line 102, in __call__
    result = self._call_fn(*args, **kwargs)
  File "/home/cuongnq1/anaconda3/envs/grand/lib/python3.9/site-packages/wandb/sdk/internal/internal_api.py", line 140, in execute
    return self.client.execute(*args, **kwargs)
  File "/home/cuongnq1/anaconda3/envs/grand/lib/python3.9/site-packages/wandb/vendor/gql-0.2.0/wandb_gql/client.py", line 52, in execute
    result = self._get_result(document, *args, **kwargs)
  File "/home/cuongnq1/anaconda3/envs/grand/lib/python3.9/site-packages/wandb/vendor/gql-0.2.0/wandb_gql/client.py", line 60, in _get_result
    return self.transport.execute(document, *args, **kwargs)
  File "/home/cuongnq1/anaconda3/envs/grand/lib/python3.9/site-packages/wandb/vendor/gql-0.2.0/wandb_gql/transport/requests.py", line 38, in execute
    request = requests.post(self.url, **post_args)
  File "/home/cuongnq1/anaconda3/envs/grand/lib/python3.9/site-packages/requests/api.py", line 117, in post
    return request('post', url, data=data, json=json, **kwargs)
  File "/home/cuongnq1/anaconda3/envs/grand/lib/python3.9/site-packages/requests/api.py", line 61, in request
    return session.request(method=method, url=url, **kwargs)
  File "/home/cuongnq1/anaconda3/envs/grand/lib/python3.9/site-packages/requests/sessions.py", line 529, in request
    resp = self.send(prep, **send_kwargs)
  File "/home/cuongnq1/anaconda3/envs/grand/lib/python3.9/site-packages/requests/sessions.py", line 645, in send
    r = adapter.send(request, **kwargs)
  File "/home/cuongnq1/anaconda3/envs/grand/lib/python3.9/site-packages/requests/adapters.py", line 532, in send
    raise ReadTimeout(e, request=request)
requests.exceptions.ReadTimeout: HTTPSConnectionPool(host='api.wandb.ai', port=443): Read timed out. (read timeout=10)
2022-04-01 16:04:45,942 INFO    MainThread:369081 [wandb_init.py:teardown():253] tearing down wandb.init
