2022-04-01 16:03:34,680 INFO    MainThread:369067 [internal.py:wandb_internal():92] W&B internal server running at pid: 369067, started at: 2022-04-01 16:03:34.680297
2022-04-01 16:03:34,686 INFO    WriterThread:369067 [datastore.py:open_for_write():77] open: /home/cuongnq1/graph-neural-pde/src/wandb/run-20220401_160334-3vq2mne0/run-3vq2mne0.wandb
2022-04-01 16:03:34,688 DEBUG   SenderThread:369067 [sender.py:send():235] send: header
2022-04-01 16:03:34,688 DEBUG   SenderThread:369067 [sender.py:send():235] send: run
2022-04-01 16:04:04,116 DEBUG   HandlerThread:369067 [handler.py:handle_request():141] handle_request: shutdown
2022-04-01 16:04:04,117 INFO    HandlerThread:369067 [handler.py:finish():778] shutting down handler
2022-04-01 16:04:04,701 INFO    WriterThread:369067 [datastore.py:close():281] close: /home/cuongnq1/graph-neural-pde/src/wandb/run-20220401_160334-3vq2mne0/run-3vq2mne0.wandb
2022-04-01 16:04:08,357 ERROR   SenderThread:369067 [retry.py:__call__():126] Retry attempt failed:
Traceback (most recent call last):
  File "/home/cuongnq1/anaconda3/envs/grand/lib/python3.9/site-packages/urllib3/connectionpool.py", line 449, in _make_request
    six.raise_from(e, None)
  File "<string>", line 3, in raise_from
  File "/home/cuongnq1/anaconda3/envs/grand/lib/python3.9/site-packages/urllib3/connectionpool.py", line 444, in _make_request
    httplib_response = conn.getresponse()
  File "/home/cuongnq1/anaconda3/envs/grand/lib/python3.9/http/client.py", line 1377, in getresponse
    response.begin()
  File "/home/cuongnq1/anaconda3/envs/grand/lib/python3.9/http/client.py", line 320, in begin
    version, status, reason = self._read_status()
  File "/home/cuongnq1/anaconda3/envs/grand/lib/python3.9/http/client.py", line 281, in _read_status
    line = str(self.fp.readline(_MAXLINE + 1), "iso-8859-1")
  File "/home/cuongnq1/anaconda3/envs/grand/lib/python3.9/socket.py", line 704, in readinto
    return self._sock.recv_into(b)
  File "/home/cuongnq1/anaconda3/envs/grand/lib/python3.9/ssl.py", line 1241, in recv_into
    return self.read(nbytes, buffer)
  File "/home/cuongnq1/anaconda3/envs/grand/lib/python3.9/ssl.py", line 1099, in read
    return self._sslobj.read(len, buffer)
socket.timeout: The read operation timed out

During handling of the above exception, another exception occurred:

Traceback (most recent call last):
  File "/home/cuongnq1/anaconda3/envs/grand/lib/python3.9/site-packages/requests/adapters.py", line 440, in send
    resp = conn.urlopen(
  File "/home/cuongnq1/anaconda3/envs/grand/lib/python3.9/site-packages/urllib3/connectionpool.py", line 785, in urlopen
    retries = retries.increment(
  File "/home/cuongnq1/anaconda3/envs/grand/lib/python3.9/site-packages/urllib3/util/retry.py", line 550, in increment
    raise six.reraise(type(error), error, _stacktrace)
  File "/home/cuongnq1/anaconda3/envs/grand/lib/python3.9/site-packages/urllib3/packages/six.py", line 770, in reraise
    raise value
  File "/home/cuongnq1/anaconda3/envs/grand/lib/python3.9/site-packages/urllib3/connectionpool.py", line 703, in urlopen
    httplib_response = self._make_request(
  File "/home/cuongnq1/anaconda3/envs/grand/lib/python3.9/site-packages/urllib3/connectionpool.py", line 451, in _make_request
    self._raise_timeout(err=e, url=url, timeout_value=read_timeout)
  File "/home/cuongnq1/anaconda3/envs/grand/lib/python3.9/site-packages/urllib3/connectionpool.py", line 340, in _raise_timeout
    raise ReadTimeoutError(
urllib3.exceptions.ReadTimeoutError: HTTPSConnectionPool(host='api.wandb.ai', port=443): Read timed out. (read timeout=10)

During handling of the above exception, another exception occurred:

Traceback (most recent call last):
  File "/home/cuongnq1/anaconda3/envs/grand/lib/python3.9/site-packages/wandb/sdk/lib/retry.py", line 102, in __call__
    result = self._call_fn(*args, **kwargs)
  File "/home/cuongnq1/anaconda3/envs/grand/lib/python3.9/site-packages/wandb/sdk/internal/internal_api.py", line 140, in execute
    return self.client.execute(*args, **kwargs)
  File "/home/cuongnq1/anaconda3/envs/grand/lib/python3.9/site-packages/wandb/vendor/gql-0.2.0/wandb_gql/client.py", line 52, in execute
    result = self._get_result(document, *args, **kwargs)
  File "/home/cuongnq1/anaconda3/envs/grand/lib/python3.9/site-packages/wandb/vendor/gql-0.2.0/wandb_gql/client.py", line 60, in _get_result
    return self.transport.execute(document, *args, **kwargs)
  File "/home/cuongnq1/anaconda3/envs/grand/lib/python3.9/site-packages/wandb/vendor/gql-0.2.0/wandb_gql/transport/requests.py", line 38, in execute
    request = requests.post(self.url, **post_args)
  File "/home/cuongnq1/anaconda3/envs/grand/lib/python3.9/site-packages/requests/api.py", line 117, in post
    return request('post', url, data=data, json=json, **kwargs)
  File "/home/cuongnq1/anaconda3/envs/grand/lib/python3.9/site-packages/requests/api.py", line 61, in request
    return session.request(method=method, url=url, **kwargs)
  File "/home/cuongnq1/anaconda3/envs/grand/lib/python3.9/site-packages/requests/sessions.py", line 529, in request
    resp = self.send(prep, **send_kwargs)
  File "/home/cuongnq1/anaconda3/envs/grand/lib/python3.9/site-packages/requests/sessions.py", line 645, in send
    r = adapter.send(request, **kwargs)
  File "/home/cuongnq1/anaconda3/envs/grand/lib/python3.9/site-packages/requests/adapters.py", line 532, in send
    raise ReadTimeout(e, request=request)
requests.exceptions.ReadTimeout: HTTPSConnectionPool(host='api.wandb.ai', port=443): Read timed out. (read timeout=10)
2022-04-01 16:04:39,287 INFO    SenderThread:369067 [dir_watcher.py:__init__():169] watching files in: /home/cuongnq1/graph-neural-pde/src/wandb/run-20220401_160334-3vq2mne0/files
2022-04-01 16:04:39,287 INFO    SenderThread:369067 [sender.py:_start_run_threads():812] run started: 3vq2mne0 with start time 1648803814
2022-04-01 16:04:39,288 INFO    SenderThread:369067 [sender.py:finish():1078] shutting down sender
2022-04-01 16:04:39,288 INFO    SenderThread:369067 [dir_watcher.py:finish():283] shutting down directory watcher
2022-04-01 16:04:40,288 INFO    SenderThread:369067 [dir_watcher.py:finish():313] scan: /home/cuongnq1/graph-neural-pde/src/wandb/run-20220401_160334-3vq2mne0/files
2022-04-01 16:04:40,289 INFO    SenderThread:369067 [dir_watcher.py:finish():327] scan save: /home/cuongnq1/graph-neural-pde/src/wandb/run-20220401_160334-3vq2mne0/files/config.yaml config.yaml
2022-04-01 16:04:40,289 INFO    SenderThread:369067 [file_pusher.py:finish():145] shutting down file pusher
2022-04-01 16:04:40,289 INFO    SenderThread:369067 [file_pusher.py:join():150] waiting for file pusher
2022-04-01 16:04:41,908 INFO    Thread-9  :369067 [upload_job.py:push():137] Uploaded file /home/cuongnq1/graph-neural-pde/src/wandb/run-20220401_160334-3vq2mne0/files/config.yaml
2022-04-01 16:04:42,789 INFO    MainThread:369067 [internal.py:handle_exit():82] Internal process exited
